Workbook

Sheet Sheet1
A1: 站点 | B1: 仓库账号 | C1: 平台 | D1: SKU | E1: 名称 | F1: 入库日期 | G1: 数量 | H1: 库龄天数 | I1: 占用体积 | J1: 仓库
A2: US | B2: 乐歌SDJT | C2: 多平台 | D2: ZMG-0190B | E2: =VLOOKUP(D2,[1]各个海外仓数据!$D$1:$E$65536,2,0) -> 抽油烟机 | F2: 2026-07-14 09:39:53 | G2: 46 | H2: 19 | I2: 5.40132 | J2: CAP
A3: US | B3: 乐歌SDJT | C3: 多平台 | D3: TM-CC-TG18-U | E3: =VLOOKUP(D3,[1]各个海外仓数据!$D$1:$E$65536,2,0) -> 配件 | F3: 2023-05-05 03:43:42 | G3: 6 | H3: 1185 | I3: 0.4383225 | J3: CAP
A4: US | B4: 乐歌SDJT | C4: 多平台 | D4: TM-CC-TG18-L | E4: =VLOOKUP(D4,[1]各个海外仓数据!$D$1:$E$65536,2,0) -> 配件 | F4: 2023-05-05 03:43:42 | G4: 4 | H4: 1185 | I4: 0.292215 | J4: CAP
A5: US | B5: 乐歌SDJT | C5: 多平台 | D5: TM-CC-TD08-U-BK | E5: =VLOOKUP(D5,[1]各个海外仓数据!$D$1:$E$65536,2,0) -> 配件 | F5: 2023-05-05 03:43:42 | G5: 3 | H5: 1185 | I5: 0.08049375 | J5: CAP
A6: US | B6: 乐歌SDJT | C6: 多平台 | D6: ZMS-1760TS | E6: =VLOOKUP(D6,[1]各个海外仓数据!$D$1:$E$65536,2,0) -> 抽油烟机 | F6: 2026-07-14 09:39:53 | G6: 25 | H6: 19 | I6: 2.0085 | J6: CAP
A7: US | B7: 乐歌SDJT | C7: 多平台 | D7: TM-CC-TD08-U-LG | E7: =VLOOKUP(D7,[1]各个海外仓数据!$D$1:$E$65536,2,0) -> 配件 | F7: 2022-02-01 03:43:42 | G7: 8 | H7: 1643 | I7: 0.21465 | J7: CAP
A8: US | B8: 乐歌SDJT | C8: 多平台 | D8: USYS0652 | E8: =VLOOKUP(D8,[1]各个海外仓数据!$D$1:$E$65536,2,0) -> 抽油烟机 | F8: 2026-05-08 10:11:01 | G8: 15 | H8: 86 | I8: 1.0732313 | J8: CAP
A9: US | B9: 乐歌SDJT | C9: 多平台 | D9: CHA18HS2A | E9: =VLOOKUP(D9,[1]各个海外仓数据!$D$1:$E$65536,2,0) -> 电陶炉 | F9: 2026-07-14 09:39:53 | G9: 25 | H9: 19 | I9: 1.0591 | J9: CAP
A10: US | B10: 乐歌SDJT | C10: 多平台 | D10: GH002-122G | E10: =VLOOKUP(D10,[1]各个海外仓数据!$D$1:$E$65536,2,0) -> 灶具 | F10: 2026-07-14 09:39:53 | G10: 37 | H10: 19 | I10: 1.70274 | J10: CAP
A11: US | B11: 乐歌SDJT | C11: 多平台 | D11: SK001-304BE | E11: =VLOOKUP(D11,[1]各个海外仓数据!$D$1:$E$65536,2,0) -> 电陶炉 | F11: 2026-05-08 10:11:01 | G11: 34 | H11: 86 | I11: 3.210552 | J11: CAP
A12: US | B12: 乐歌SDJT | C12: 多平台 | D12: YYB1670T | E12: =VLOOKUP(D12,[1]各个海外仓数据!$D$1:$E$65536,2,0) -> 抽油烟机 | F12: 2026-07-14 09:39:53 | G12: 17 | H12: 19 | I12: 1.6031978 | J12: CAP
A13: US | B13: 乐歌SDJT | C13: 多平台 | D13: US0475BTC | E13: =VLOOKUP(D13,[1]各个海外仓数据!$D$1:$E$65536,2,0) -> 抽油烟机 | F13: 2026-05-08 10:11:01 | G13: 5 | H13: 86 | I13: 0.50204 | J13: CAP
A14: US | B14: 乐歌SDJT | C14: 多平台 | D14: ICA350ZSF | E14: 制冰机 | F14: 2026-07-28 12:34:30 | G14: 30 | H14: 5 | I14: 3.2154975 | J14: CAP
A15: US | B15: 乐歌SDJT | C15: 多平台 | D15: USGF3976WH-T | E15: =VLOOKUP(D15,[1]各个海外仓数据!$D$1:$E$65536,2,0) -> 抽油烟机 | F15: 2026-07-14 09:39:53 | G15: 48 | H15: 19 | I15: 3.239676 | J15: CAP
A16: US | B16: 乐歌SDJT | C16: 多平台 | D16: TM-CC-TG18-U-LG | E16: =VLOOKUP(D16,[1]各个海外仓数据!$D$1:$E$65536,2,0) -> 配件 | F16: 2022-02-01 03:43:42 | G16: 4 | H16: 1643 | I16: 0.292215 | J16: CAP
A17: US | B17: 乐歌SDJT | C17: 多平台 | D17: PH7DU10730TA | E17: =VLOOKUP(D17,[1]各个海外仓数据!$D$1:$E$65536,2,0) -> 泳池热泵机 | F17: 2026-05-27 11:19:06 | G17: 10 | H17: 67 | I17: 3.0480425 | J17: CAP
A18: US | B18: 乐歌SDJT | C18: 多平台 | D18: US1001G90BPA | E18: =VLOOKUP(D18,[1]各个海外仓数据!$D$1:$E$65536,2,0) -> 抽油烟机 | F18: 2026-05-14 16:43:35 | G18: 1 | H18: 80 | I18: 0.1235 | J18: CAP
A19: US | B19: 乐歌SDJT | C19: 多平台 | D19: US1001G90BPA | E19: =VLOOKUP(D19,[1]各个海外仓数据!$D$1:$E$65536,2,0) -> 抽油烟机 | F19: 2026-04-07 12:05:20 | G19: 18 | H19: 117 | I19: 2.223 | J19: CAP
A20: US | B20: 乐歌SDJT | C20: 多平台 | D20: USGD1775BCK | E20: =VLOOKUP(D20,[1]各个海外仓数据!$D$1:$E$65536,2,0) -> 抽油烟机 | F20: 2026-05-08 10:11:01 | G20: 19 | H20: 86 | I20: 1.87872 | J20: CAP
A21: US | B21: 乐歌SDJT | C21: 多平台 | D21: USGI0290B | E21: =VLOOKUP(D21,[1]各个海外仓数据!$D$1:$E$65536,2,0) -> 抽油烟机 | F21: 2026-07-14 09:39:53 | G21: 22 | H21: 19 | I21: 6.4582017 | J21: CAP
A22: US | B22: 乐歌SDJT | C22: 多平台 | D22: RHA30GDS6 | E22: =VLOOKUP(D22,[1]各个海外仓数据!$D$1:$E$65536,2,0) -> 抽油烟机 | F22: 2026-07-14 09:39:53 | G22: 39 | H22: 19 | I22: 3.4749 | J22: CAP
A23: US | B23: 乐歌SDJT | C23: 多平台 | D23: USCC-TD08-EXT | E23: =VLOOKUP(D23,[1]各个海外仓数据!$D$1:$E$65536,2,0) -> 配件 | F23: 2026-07-14 09:39:53 | G23: 14 | H23: 19 | I23: 0.710787 | J23: CAP
A24: US | B24: 乐歌SDJT | C24: 多平台 | D24: USGD1775A | E24: =VLOOKUP(D24,[1]各个海外仓数据!$D$1:$E$65536,2,0) -> 抽油烟机 | F24: 2026-07-14 09:39:53 | G24: 50 | H24: 19 | I24: 4.944 | J24: CAP
A25: US | B25: 乐歌SDJT | C25: 多平台 | D25: ZMS-2560 | E25: =VLOOKUP(D25,[1]各个海外仓数据!$D$1:$E$65536,2,0) -> 抽油烟机 | F25: 2026-07-14 09:39:53 | G25: 41 | H25: 19 | I25: 2.0898161 | J25: CAP
A26: US | B26: 乐歌SDJT | C26: 多平台 | D26: ZMS-3976-T | E26: =VLOOKUP(D26,[1]各个海外仓数据!$D$1:$E$65536,2,0) -> 抽油烟机 | F26: 2026-06-05 15:07:32 | G26: 1 | H26: 58 | I26: 0.06749325 | J26: CAP
A27: US | B27: 乐歌SDJT | C27: 多平台 | D27: ZMS-3976-T | E27: =VLOOKUP(D27,[1]各个海外仓数据!$D$1:$E$65536,2,0) -> 抽油烟机 | F27: 2026-05-08 10:11:01 | G27: 129 | H27: 86 | I27: 8.7066293 | J27: CAP
A28: US | B28: 乐歌SDJT | C28: 多平台 | D28: ICAFTSZS7-L | E28: 制冰机 | F28: 2026-07-28 12:33:27 | G28: 20 | H28: 5 | I28: 8.08488 | J28: CAP
A29: US | B29: 乐歌SDJT | C29: 多平台 | D29: ICAFTSZS7-U | E29: 制冰机 | F29: 2026-07-28 12:35:24 | G29: 20 | H29: 5 | I29: 4.629376 | J29: CAP
A30: US | B30: 乐歌SDJT | C30: 多平台 | D30: ICAT36SL001A | E30: 制冰机 | F30: 2026-07-28 09:12:29 | G30: 64 | H30: 5 | I30: 7.79868 | J30: CAP
A31: US | B31: 乐歌SDJT | C31: 多平台 | D31: ICAZLBS8A | E31: =VLOOKUP(D31,[1]各个海外仓数据!$D$1:$E$65536,2,0) -> 冰槽 | F31: 2026-05-27 15:22:14 | G31: 7 | H31: 67 | I31: 0.67032 | J31: CAP
A32: US | B32: 乐歌SDJT | C32: 多平台 | D32: CH30K230905A | E32: =VLOOKUP(D32,[1]各个海外仓数据!$D$1:$E$65536,2,0) -> 电陶炉 | F32: 2026-07-14 09:39:53 | G32: 26 | H32: 19 | I32: 2.420847 | J32: CAP
A33: US | B33: 乐歌SDJT | C33: 多平台 | D33: ICBZS40SS01A | E33: =VLOOKUP(D33,[1]各个海外仓数据!$D$1:$E$65536,2,0) -> 制冰机 | F33: 2026-07-01 19:14:12 | G33: 175 | H33: 32 | I33: 31.447237 | J33: CAP
A34: US | B34: 乐歌SDJT | C34: 多平台 | D34: ICBZS40SS01A | E34: =VLOOKUP(D34,[1]各个海外仓数据!$D$1:$E$65536,2,0) -> 制冰机 | F34: 2026-05-27 13:30:02 | G34: 30 | H34: 67 | I34: 5.390955 | J34: CAP
A35: US | B35: 乐歌SDJT | C35: 多平台 | D35: ICBZS40SS01A | E35: =VLOOKUP(D35,[1]各个海外仓数据!$D$1:$E$65536,2,0) -> 制冰机 | F35: 2026-05-26 13:38:26 | G35: 100 | H35: 68 | I35: 17.96985 | J35: CAP
A36: US | B36: 乐歌SDJT | C36: 多平台 | D36: ICBZS40SS01A | E36: =VLOOKUP(D36,[1]各个海外仓数据!$D$1:$E$65536,2,0) -> 制冰机 | F36: 2026-05-05 15:03:21 | G36: 2 | H36: 89 | I36: 0.359397 | J36: CAP
A37: US | B37: 乐歌SDJT | C37: 多平台 | D37: USGD2475B | E37: =VLOOKUP(D37,[1]各个海外仓数据!$D$1:$E$65536,2,0) -> 抽油烟机 | F37: 2026-04-07 12:05:20 | G37: 15 | H37: 117 | I37: 1.5552 | J37: CAP
A38: US | B38: 乐歌SDJT | C38: 多平台 | D38: RHA30BLC2 | E38: =VLOOKUP(D38,[1]各个海外仓数据!$D$1:$E$65536,2,0) -> 抽油烟机 | F38: 2026-07-14 09:39:53 | G38: 50 | H38: 19 | I38: 9.047 | J38: CAP
A39: US | B39: 乐歌SDJT | C39: 多平台 | D39: SK002-304BI | E39: =VLOOKUP(D39,[1]各个海外仓数据!$D$1:$E$65536,2,0) -> 电磁炉 | F39: 2025-04-23 13:33:37 | G39: 2 | H39: 466 | I39: 0.16224 | J39: CAP
A40: US | B40: 乐歌SDJT | C40: 多平台 | D40: CHA90H365 | E40: =VLOOKUP(D40,[1]各个海外仓数据!$D$1:$E$65536,2,0) -> 电陶炉 | F40: 2026-05-08 10:11:01 | G40: 5 | H40: 86 | I40: 0.5363325 | J40: CAP
...

Sheet Sheet2

Sheet Sheet3
